Workbook

Sheet Income Statement
A1: Fiscal Year | B1: FY 2021 | C1: FY 2022 | D1: FY 2023 | E1: FY 2024 | F1: FY 2025
A2: Revenue | B2: 78598 | C2: 87327 | D2: 68902 | E2: 61444 | F2: 59657
A3: Revenue Growth | B3: 0.3288 | C3: 0.1111 | D3: -0.211 | E3: -0.1082 | F3: -0.0291
A4: Cost of Revenue | B4: 59091 | C4: 66697 | D4: 52506 | E4: 46534 | F4: 45527
A5: Gross Profit | B5: 19507 | C5: 20630 | D5: 16396 | E5: 14910 | F5: 14130
A6: Selling, General & Admin | B6: 9902 | C6: 11201 | D6: 10379 | E6: 9025 | F6: 8883
A7: Research & Development | B7: 2216 | C7: 2298 | D7: 2130 | E7: 1969 | F7: 1995
A8: Other Operating Expenses | B8: -115 | C8: 275 | D8: 1046 | E8: 1432 | F8: 779
A9: Operating Expenses | B9: 12040 | C9: 13774 | D9: 13555 | E9: 12426 | F9: 11657
A10: Operating Income | B10: 7467 | C10: 6856 | D10: 2841 | E10: 2484 | F10: 2473
A11: Interest Expense | B11: -506 | C11: -631 | D11: -868 | E11: -929 | F11: -924
A12: Interest & Investment Income | B12: 257 | C12: 354 | D12: 453 | E12: 512 | F12: 406
A13: Earnings From Equity Investments | B13: 960 | C13: -4499 | D13: 78 | E13: 653 | F13: 1055
... A19: Gain (Loss) on Sale of Assets | B19: 129 | C19: 250 | D19: 43 | E19: 65 | F19: 668
A20: Asset Writedown | B20: -103 | C20: -375 | D20: 6 | E20: - | F20: 8
A21: Pretax Income | B21: 7448 | C21: 1190 | D21: 1420 | E21: 1861 | F21: 2448
A22: Income Tax Expense | B22: 1430 | C22: 1581 | D22: 1041 | E22: 573 | F22: 907
A23: Earnings From Continuing Operations | B23: 6018 | C23: -391 | D23: 379 | E23: 1288 | F23: 1541
A24: Earnings From Discontinued Operations | B24: -36 | C24: - | D24: - | E24: 165 | F24: 185
A25: Net Income to Company | B25: 5982 | C25: -391 | D25: 379 | E25: 1453 | F25: 1726
A26: Minority Interest in Earnings | B26: -459 | C26: -236 | D26: -154 | E26: -155 | F26: -107
A27: Net Income | B27: 5523 | C27: -627 | D27: 225 | E27: 1298 | F27: 1619
A28: Net Income to Common | B28: 5523 | C28: -627 | D28: 225 | E28: 1298 | F28: 1619
A29: Net Income Growth | B29: - | C29: - | D29: - | E29: 4.7689 | F29: 0.2473
A30: Shares Outstanding (Basic) | B30: 918 | C30: 902 | D30: 893 | E30: 893 | F30: 892
A31: Shares Outstanding (Diluted) | B31: 920 | C31: 902 | D31: 895 | E31: 895 | F31: 894
A32: Shares Change | B32: 0.0003 | C32: -0.0204 | D32: -0.0074 | E32: -0.0001 | F32: -0.001
A33: EPS (Basic) | B33: 6.01 | C33: -0.7 | D33: 0.25 | E33: 1.45 | F33: 1.82
A34: EPS (Diluted) | B34: 6 | C34: -0.7 | D34: 0.25 | E34: 1.45 | F34: 1.81
A35: EPS Growth | B35: - | C35: - | D35: - | E35: 4.8 | F35: 0.2483

Sheet Balance Sheet
A1: Assets
A2: Fiscal Year | B2: FY 2021 | C2: FY 2022 | D2: FY 2023 | E2: FY 2024 | F2: FY 2025
A3: Cash & Equivalents | B3: 2624 | C3: 2516 | D3: 2624 | E3: 2914 | F3: 2670
A4: Short-Term Investments | B4: 208 | C4: 232 | D4: 53 | E4: 67 | F4: 89
A5: Trading Asset Securities | B5: 1554 | C5: 1939 | D5: 1139 | E5: - | F5: 1327
A6: Cash & Short-Term Investments | B6: 4386 | C6: 4687 | D6: 3816 | E6: 2981 | F6: 4086
A7: Cash Growth | B7: -0.2858 | C7: 0.0686 | D7: -0.1858 | E7: -0.2188 | F7: 0.3707
A8: Accounts Receivable | B8: 11946 | C8: 12057 | D8: 10417 | E8: 10393 | F8: 8327
A9: Other Receivables | B9: 2187 | C9: 2485 | D9: 1761 | E9: 3996 | F9: 1623
A10: Receivables | B10: 14282 | C10: 14645 | D10: 12360 | E10: 14389 | F10: 10088
A11: Inventory | B11: 13868 | C11: 16028 | D11: 13876 | E11: 13681 | F11: 12168
A12: Prepaid Expenses | B12: 327 | C12: 285 | D12: 225 | E12: - | F12: 207
A13: Other Current Assets | B13: 2188 | C13: 1777 | D13: 1195 | E13: 181 | F13: 5135
A14: Total Current Assets | B14: 35051 | C14: 37422 | D14: 31472 | E14: 31232 | F14: 31684
A15: Property, Plant & Equipment | B15: 17871 | C15: 17908 | D15: 17639 | E15: 17773 | F15: 20325
A16: Long-Term Investments | B16: 12958 | C16: 8121 | D16: 7671 | E16: 6975 | F16: 6048
A17: Goodwill | B17: 7521 | C17: 7695 | D17: 7499 | E17: 7720 | F17: 6553
A18: Other Intangible Assets | B18: 5978 | C18: 5578 | D18: 4717 | E18: 4263 | F18: 3139
A19: Long-Term Accounts Receivable | B19: 40 | C19: 32 | D19: 30 | E19: 29 | F19: 27
A20: Long-Term Deferred Tax Assets | B20: 2600 | C20: 880 | D20: 617 | E20: 574 | F20: 544
A21: Other Long-Term Assets | B21: 5322 | C21: 6791 | D21: 7693 | E21: 11797 | F21: 7834
A22: Total Assets | B22: 87383 | C22: 84472 | D22: 77395 | E22: 80415 | F22: 76174
A24: Average Accounts Receivable | C24: =(B8+C8)/2 -> 12001.5 | D24: =(C8+D8)/2 -> 11237 | E24: =(D8+E8)/2 -> 10405 | F24: =(E8+F8)/2 -> 9360
A26: Liabilities
A27: Fiscal Year | B27: FY 2021 | C27: FY 2022 | D27: FY 2023 | E27: FY 2024 | F27: FY 2025
A28: Accounts Payable | B28: 7826 | C28: 8434 | D28: 6741 | E28: 6923 | F28: 5484
A29: Accrued Expenses | B29: 2374 | C29: 2054 | D29: 1414 | E29: 1579 | F29: 1671
A30: Short-Term Debt | B30: 248 | C30: 654 | D30: - | E30: - | F30: -
A31: Current Portion of Long-Term Debt | B31: 3677 | C31: 3615 | D31: 2597 | E31: 3200 | F31: 3167
A32: Current Portion of Leases | B32: 334 | C32: 329 | D32: 350 | E32: 340 | F32: 342
A33: Current Income Taxes Payable | B33: 1161 | C33: 995 | D33: 442 | E33: 404 | F33: 213
A34: Current Unearned Revenue | B34: 1021 | C34: 1016 | D34: 853 | E34: 803 | F34: 709
A35: Other Current Liabilities | B35: 3440 | C35: 3343 | D35: 3474 | E35: 3790 | F35: 4825
A36: Total Current Liabilities | B36: 20081 | C36: 20440 | D36: 15871 | E36: 17039 | F36: 16411
A37: Long-Term Debt | B37: 13799 | C37: 15192 | D37: 17101 | E37: 19132 | F37: 18488
A38: Long-Term Leases | B38: 1078 | C38: 1159 | D38: 1299 | E38: 1323 | F38: 1212
A39: Long-Term Unearned Revenue | B39: 218 | C39: 192 | D39: 160 | E39: 217 | F39: 238
A40: Pension & Post-Retirement Benefits | B40: 6160 | C40: 2810 | D40: 2896 | E40: 2403 | F40: 1832
A41: Long-Term Deferred Tax Liabilities | B41: 1499 | C41: 1543 | D41: 1140 | E41: 1005 | F41: 953
A42: Other Long-Term Liabilities | B42: 2467 | C42: 2213 | D42: 2283 | E42: 2413 | F42: 2703
...

Sheet Cash Flow Statement
A1: Operating Activities
A2: Fiscal Year | B2: FY 2021 | C2: FY 2022 | D2: FY 2023 | E2: FY 2024 | F2: FY 2025
A3: Net Income | B3: ='Income Statement'!B27 -> 5523 | C3: ='Income Statement'!C27 -> -627 | D3: ='Income Statement'!D27 -> 225 | E3: ='Income Statement'!E27 -> 1298 | F3: ='Income Statement'!F27 -> 1619
A4: Depreciation & Amortization | B4: 3518 | C4: 3800 | D4: 3769 | E4: 3647 | F4: 3580
A5: Other Amortization | B5: 25 | C5: 27 | D5: 29 | E5: - | F5: -
A6: Loss (Gain) From Sale of Assets | B6: -611 | C6: -1 | D6: -103 | E6: -57 | F6: -842
A7: Asset Writedown & Restructuring Costs | B7: 144 | C7: 373 | D7: 1143 | E7: 753 | F7: 404
A8: Loss (Gain) on Equity Investments | B8: - | C8: 4499 | D8: 544 | E8: -212 | F8: 276
A9: Other Operating Activities | B9: -1 | C9: 1688 | D9: 5 | E9: 398 | F9: -230
A10: Change in Accounts Receivable | B10: -1272 | C10: 219 | D10: 1443 | E10: 42 | F10: 530
A11: Change in Inventory | B11: -3304 | C11: -1991 | D11: 1896 | E11: 222 | F11: 263
A12: Change in Accounts Payable | B12: - | C12: 451 | D12: -1544 | E12: 96 | F12: -736
A13: Change in Other Net Operating Assets | B13: 3223 | C13: -729 | D13: 704 | E13: 511 | F13: 564
A14: Operating Cash Flow | B14: 7245 | C14: 7709 | D14: 8111 | E14: 6946 | F14: 5610
A15: Operating Cash Flow Growth | B15: 0.3384 | C15: 0.064 | D15: 0.0521 | E15: -0.1436 | F15: -0.1923
A17: Investing Activities
A18: Fiscal Year | B18: FY 2021 | C18: FY 2022 | D18: FY 2023 | E18: FY 2024 | F18: FY 2025
A19: Capital Expenditures | B19: -3532 | C19: -4375 | D19: -5395 | E19: -6198 | F19: -4267
A20: Cash Acquisitions | B20: -600 | C20: -13 | D20: -5 | E20: -202 | F20: -1
A21: Divestitures | B21: 1030 | C21: 691 | D21: 32 | E21: 75 | F21: 871
A22: Investment in Securities | B22: -994 | C22: -1273 | D22: -1063 | E22: 436 | F22: -1121
A23: Other Investing Activities | B23: 1474 | C23: 1192 | D23: 1440 | E23: 808 | F23: 1310
A24: Investing Cash Flow | B24: -2622 | C24: -3778 | D24: -4991 | E24: -5081 | F24: -3208
A26: Financing Activities
A27: Fiscal Year | B27: FY 2021 | C27: FY 2022 | D27: FY 2023 | E27: FY 2024 | F27: FY 2025
A28: Long-Term Debt Issued | B28: 7627 | C28: 10896 | D28: 9503 | E28: 6362 | F28: 6394
A29: Long-Term Debt Repaid | B29: -10772 | C29: -10330 | D29: -9244 | E29: -4579 | F29: -6369
A30: Net Debt Issued (Repaid) | B30: -3145 | C30: 566 | D30: 259 | E30: 1783 | F30: 25
A31: Repurchase of Common Stock | B31: - | C31: -1331 | D31: -70 | E31: -46 | F31: -355
A32: Common Dividends Paid | B32: -3031 | C32: -3072 | D32: -3034 | E32: -3035 | F32: -2086
A33: Other Financing Activities | B33: -281 | C33: -176 | D33: -60 | E33: -249 | F33: -
A34: Financing Cash Flow | B34: -6457 | C34: -4013 | D34: -2905 | E34: -1547 | F34: -2416
A37: Fiscal Year | B37: FY 2021 | C37: FY 2022 | D37: FY 2023 | E37: FY 2024 | F37: FY 2025
A38: Foreign Exchange Rate Adjustments | B38: 131 | C38: -25 | D38: -106 | E38: -21 | F38: -88
A39: Miscellaneous Cash Flow Adjustments | B39: -8 | C39: -1 | D39: - | E39: - | F39: -1
A40: Net Cash Flow | B40: -1711 | C40: -108 | D40: 109 | E40: 297 | F40: -103

Sheet DCF Valuation
A1: BASF SE — Discounted Cash Flow Valuation
A2: Model basis | B2: FY2025A historical data + FY2026F–FY2028F forecast inputs retained from original project
A3: Valuation method | B3: FCFF / UFCF discounted at WACC
A4: Currency | B4: € million, except per-share data
A6: 1. DCF Forecast and Unlevered Free Cash Flow
A7: Metric | B7: FY2026F | C7: FY2027F | D7: FY2028F | E7: Formula / note
A8: EBIT | B8: 3751.5019 | C8: 3901.562 | D8: 4018.6088 | E8: Operating profit before interest and tax
A9: Tax Rate | B9: 0.3 | C9: 0.3 | D9: 0.3 | E9: Normalized tax rate
A10: Tax on EBIT | B10: =B8*B9 -> 1125.4506 | C10: =C8*C9 -> 1170.4686 | D10: =D8*D9 -> 1205.5827 | E10: ebit * tax rate
A11: NOPAT | B11: =B8-B10 -> 2626.0513 | C11: =C8-C10 -> 2731.0934 | D11: =D8-D10 -> 2813.0262
A12: + D&A | B12: 3317.8819 | C12: 3450.5971 | D12: 3554.115 | E12: Non-cash depreciation and amortisation
A13: − CapEx | B13: -4372.5972 | C13: -4547.5011 | D13: -4683.9262 | E13: Capital expenditure
A14: − Change in NWC | B14: -661.42006 | C14: -626.8968 | D14: -488.97951 | E14: Change in net working capital
A15: UFCF | B15: =B11+B12+B13+B14 -> 909.9159 | C15: =C11+C12+C13+C14 -> 1007.2926 | D15: =D11+D12+D13+D14 -> 1194.2356 | E15: nopat + d&a + capex + change in nwc
A16: Discount Factor | B16: =1/(1+$B$32)^1 -> 0.94523049 | C16: =1/(1+$B$32)^2 -> 0.89346068 | D16: =1/(1+$B$32)^3 -> 0.84452627 | E16: 1 / (1 +@ wacc)^t
A17: Present Value of UFCF | B17: =B15*B16 -> 860.08025 | C17: =C15*C16 -> 899.97632 | D17: =D15*D16 -> 1008.5633 | E17: ufcf * discount factor
A20: 2. WACC Calculation
A21: Input | B21: Value | C21: Formula / Source
A22: Risk-Free Rate | B22: 0.035 | C22: 10-year German Bund assumption used in original project
A23: Beta | B23: 0.75 | C23: 5-year monthly beta used in original project
A24: Market Risk Premium | B24: 0.0508 | C24: Germany equity risk premium used in original project
A25: Cost of Equity | B25: =B22+B23*B24 -> 0.0731 | C25: CAPM = Rf + β × MRP
A26: Pre-Tax Cost of Debt | B26: 0.042012413 | C26: FY2025 interest expense / average debt assumption used in original project
A27: Tax Rate | B27: 0.3 | C27: Normalized tax rate
A28: After-Tax Cost of Debt | B28: =B26*(1-B27) -> 0.029408689 | C28: Pre-tax cost of debt × (1 − tax rate)
A29: Market Value of Equity | B29: 39700 | C29: Original project assumption
A30: Market Value of Debt | B30: 21088 | C30: Original project assumption
A31: Total Capital | B31: =B29+B30 -> 60788 | C31: Equity + debt
A32: WACC | B32: =(B29/B31)*B25+(B30/B31)*B28 -> 0.057943022 | C32: E/V × Ke + D/V × Kd × (1−T)
A35: 3. Enterprise Value to Equity Value
A36: PV of Forecast UFCF | B36: =SUM(B17:D17) -> 2768.6199
A37: Terminal Growth Rate | B37: 0.02
A38: Terminal Value | B38: =D15*(1+B37)/(B32-B37) -> 32103.934
A39: PV of Terminal Value | B39: =B38/(1+B32)^3 -> 27112.616
A40: Enterprise Value | B40: =B36+B39 -> 29881.236
A41: Net Debt FY2025A | B41: 18329
A42: Equity Value | B42: =B40-B41 -> 11552.236
A43: Shares Outstanding (m) | B43: 884.325
A44: Implied Share Price (€) | B44: =B42/B43 -> 13.063337
A45: Current BASF Share Price (€) | B45: 51.83
...

Sheet Covestro AG
A1: Covestro AG (FRA:1COV)
A2: Income Statement
A3: Fiscal Year | B3: TTM | C3: FY 2025 | D3: FY 2024 | E3: FY 2023 | F3: FY 2022 | G3: FY 2021
A4: Period Ending | B4: Jun 30, 2026 | C4: Dec 31, 2025 | D4: Dec 31, 2024 | E4: Dec 31, 2023 | F4: Dec 31, 2022 | G4: Dec 31, 2021
A5: Revenue | B5: 12815 | C5: 12942 | D5: 14179 | E5: 14377 | F5: 17968 | G5: 15903
A6: Revenue Growth | B6: -0.0737 | C6: -0.087 | D6: -0.0138 | E6: -0.1999 | F6: 0.1298 | G6: 0.4854
A7: Cost of Revenue | B7: 10711 | C7: 11067 | D7: 12002 | E7: 12047 | F7: 15021 | G7: 11475
A8: Gross Profit | B8: 2104 | C8: 1875 | D8: 2177 | E8: 2330 | F8: 2947 | G8: 4428
A9: Selling, General & Admin | B9: 1805 | C9: 1817 | D9: 1870 | E9: 1865 | F9: 1975 | G9: 1861
A10: Research & Development | B10: 333 | C10: 340 | D10: 392 | E10: 374 | F10: 361 | G10: 341
A11: Other Operating Expenses | B11: -98 | C11: -54 | D11: -38 | E11: -78 | F11: -51 | G11: 14
A12: Operating Expenses | B12: 2040 | C12: 2103 | D12: 2224 | E12: 2161 | F12: 2285 | G12: 2216
A13: Operating Income | B13: 64 | C13: -228 | D13: -47 | E13: 169 | F13: 662 | G13: 2212
A14: Interest Expense | B14: -132 | C14: -146 | D14: -145 | E14: -160 | F14: -148 | G14: -79
A15: Interest & Investment Income | B15: 43 | C15: 36 | D15: 56 | E15: 77 | F15: 69 | G15: 43
A16: Earnings From Equity Investments | B16: -16 | C16: -15 | D16: -2 | E16: -19 | F16: -15 | G16: -13
... A19: EBT Excluding Unusual Items | B19: -26 | C19: -362 | D19: -147 | E19: 72 | F19: 543 | G19: 2153
A20: Merger & Restructuring Charges | B20: - | C20: - | D20: - | E20: - | F20: - | G20: -3
A21: Impairment of Goodwill | B21: -42 | C21: -42 | D21: - | E21: -7 | F21: -33 | G21: -
A22: Gain (Loss) on Sale of Assets | B22: 65 | C22: 65 | D22: 46 | E22: - | F22: - | G22: -
A23: Asset Writedown | B23: -153 | C23: -153 | D23: 19 | E23: 8 | F23: -380 | G23: 2
A24: Other Unusual Items | B24: -75 | C24: -75 | D24: - | E24: -75 | F24: - | G24: 33
A25: Pretax Income | B25: -156 | C25: -492 | D25: -27 | E25: 73 | F25: 130 | G25: 2185
A26: Income Tax Expense | B26: 144 | C26: 151 | D26: 245 | E26: 275 | F26: 411 | G26: 566
A27: Earnings From Continuing Operations | B27: -300 | C27: -643 | D27: -272 | E27: -202 | F27: -281 | G27: 1619
A28: Minority Interest in Earnings | B28: -5 | C28: -1 | D28: 6 | E28: 4 | F28: 9 | G28: -3
A29: Net Income | B29: -305 | C29: -644 | D29: -266 | E29: -198 | F29: -272 | G29: 1616
A30: Net Income to Common | B30: -305 | C30: -644 | D30: -266 | E30: -198 | F30: -272 | G30: 1616
A31: Net Income Growth | B31: - | C31: - | D31: - | E31: - | F31: - | G31: 2.5207
A32: Shares Outstanding (Basic) | B32: 199 | C32: 190 | D32: 189 | E32: 189 | F32: 191 | G32: 193
A33: Shares Outstanding (Diluted) | B33: 199 | C33: 190 | D33: 189 | E33: 189 | F33: 191 | G33: 193
A34: Shares Change | B34: 0.0561 | C34: 0.006 | D34: -0.0028 | E34: -0.0088 | F34: -0.0116 | G34: 0.0446
A35: EPS (Basic) | B35: -1.53 | C35: -3.39 | D35: -1.41 | E35: -1.05 | F35: -1.42 | G35: 8.37
A36: EPS (Diluted) | B36: -1.53 | C36: -3.39 | D36: -1.41 | E36: -1.05 | F36: -1.42 | G36: 8.37
A37: EPS Growth | B37: - | C37: - | D37: - | E37: - | F37: - | G37: 2.3733
A39: Balance Sheet
A40: Assets
A41: Fiscal Year | B41: TTM | C41: FY 2025 | D41: FY 2024 | E41: FY 2023 | F41: FY 2022 | G41: FY 2021
A42: Period Ending | B42: Jun 30, 2026 | C42: Dec 31, 2025 | D42: Dec 31, 2024 | E42: Dec 31, 2023 | F42: Dec 31, 2022 | G42: Dec 31, 2021
A43: Cash & Equivalents | B43: 474 | C43: 648 | D43: 509 | E43: 625 | F43: 1198 | G43: 649
...

Sheet Evonik Industries
A1: Evonik Industries AG (ETR:EVK)
A3: Income Statement
A4: Fiscal Year | B4: TTM | C4: FY 2025 | D4: FY 2024 | E4: FY 2023 | F4: FY 2022 | G4: FY 2021
A5: Period Ending | B5: Jun 30, 2026 | C5: Dec 31, 2025 | D5: Dec 31, 2024 | E5: Dec 31, 2023 | F5: Dec 31, 2022 | G5: Dec 31, 2021
A6: Revenue | B6: 14112 | C6: 14069 | D6: 15157 | E6: 15267 | F6: 18488 | G6: 14955
A7: Revenue Growth | B7: -0.0405 | C7: -0.0718 | D7: -0.0072 | E7: -0.1742 | F7: 0.2362 | G7: 0.2259
A8: Cost of Revenue | B8: 10583 | C8: 10609 | D8: 11181 | E8: 11876 | F8: 14162 | G8: 10887
A9: Gross Profit | B9: 3529 | C9: 3460 | D9: 3976 | E9: 3391 | F9: 4326 | G9: 4068
A10: Selling, General & Admin | B10: 2196 | C10: 2207 | D10: 2396 | E10: 2315 | F10: 2566 | G10: 2253
A11: Research & Development | B11: 398 | C11: 419 | D11: 447 | E11: 433 | F11: 460 | G11: 464
A12: Other Operating Expenses | B12: 7 | C12: -71 | D12: 1 | E12: 36 | F12: -71 | G12: 76
A13: Operating Expenses | B13: 2601 | C13: 2555 | D13: 2844 | E13: 2784 | F13: 2955 | G13: 2793
A14: Operating Income | B14: 928 | C14: 905 | D14: 1132 | E14: 607 | F14: 1371 | G14: 1275
A15: Interest Expense | B15: -218 | C15: -218 | D15: -212 | E15: -244 | F15: -122 | G15: -129
A16: Interest & Investment Income | B16: 68 | C16: 82 | D16: 71 | E16: 117 | F16: 144 | G16: 64
A17: Earnings From Equity Investments | B17: 12 | C17: 14 | D17: 21 | E17: 10 | F17: 12 | G17: 8
... A21: Merger & Restructuring Charges | B21: -96 | C21: -56 | D21: -429 | E21: -304 | F21: -135 | G21: -19
A22: Gain (Loss) on Sale of Investments | B22: 7 | C22: 7 | D22: 2 | E22: 12 | F22: 36 | G22: -
A23: Gain (Loss) on Sale of Assets | B23: -2 | C23: -17 | D23: -24 | E23: -14 | F23: 11 | G23: -29
A24: Asset Writedown | B24: -218 | C24: -213 | D24: -78 | E24: - | F24: 3 | G24: -50
A25: Other Unusual Items | B25: -190 | C25: -41 | D25: -11 | E25: -463 | F25: -330 | G25: -
A26: Pretax Income | B26: 265 | C26: 422 | D26: 434 | E26: -351 | F26: 923 | G26: 1085
A27: Income Tax Expense | B27: 133 | C27: 145 | D27: 194 | E27: 101 | F27: 369 | G27: 316
A28: Earnings From Continuing Operations | B28: 132 | C28: 277 | D28: 240 | E28: -452 | F28: 554 | G28: 769
A29: Earnings From Discontinued Operations | B29: - | C29: - | D29: - | E29: - | F29: 1 | G29: -2
A30: Net Income to Company | B30: 132 | C30: 277 | D30: 240 | E30: -452 | F30: 555 | G30: 767
A31: Minority Interest in Earnings | B31: -11 | C31: -12 | D31: -18 | E31: -13 | F31: -15 | G31: -21
A32: Net Income | B32: 121 | C32: 265 | D32: 222 | E32: -465 | F32: 540 | G32: 746
A33: Net Income to Common | B33: 121 | C33: 265 | D33: 222 | E33: -465 | F33: 540 | G33: 746
A34: Net Income Growth | B34: -0.7146 | C34: 0.1937 | D34: - | E34: - | F34: -0.2761 | G34: 0.6043
A35: Shares Outstanding (Basic) | B35: 466 | C35: 466 | D35: 466 | E35: 466 | F35: 466 | G35: 466
A36: Shares Outstanding (Diluted) | B36: 466 | C36: 466 | D36: 466 | E36: 466 | F36: 466 | G36: 466
A37: Shares Change | B37: 0.008 | C37: - | D37: - | E37: - | F37: - | G37: -
A38: EPS (Basic) | B38: 0.26 | C38: 0.57 | D38: 0.48 | E38: -1 | F38: 1.16 | G38: 1.6
A39: EPS (Diluted) | B39: 0.26 | C39: 0.57 | D39: 0.48 | E39: -1 | F39: 1.16 | G39: 1.6
A40: EPS Growth | B40: -0.7169 | C40: 0.1937 | D40: - | E40: - | F40: -0.2761 | G40: 0.6043
A42: Balance Sheet
A43: Assets
A44: Fiscal Year | B44: TTM | C44: FY 2025 | D44: FY 2024 | E44: FY 2023 | F44: FY 2022 | G44: FY 2021
A45: Period Ending | B45: Jun 30, 2026 | C45: Dec 31, 2025 | D45: Dec 31, 2024 | E45: Dec 31, 2023 | F45: Dec 31, 2022 | G45: Dec 31, 2021
...

Sheet Arkema
A1: Arkema S.A. (EPA:AKE)
A3: Income Statement
A4: Fiscal Year | B4: TTM | C4: FY 2025 | D4: FY 2024 | E4: FY 2023 | F4: FY 2022 | G4: FY 2021
A5: Period Ending | B5: Jun 30, 2026 | C5: Dec 31, 2025 | D5: Dec 31, 2024 | E5: Dec 31, 2023 | F5: Dec 31, 2022 | G5: Dec 31, 2021
A6: Revenue | B6: 8901 | C6: 9068 | D6: 9544 | E6: 9514 | F6: 11550 | G6: 9519
A7: Revenue Growth | B7: -0.0574 | C7: -0.0499 | D7: 0.0032 | E7: -0.1763 | F7: 0.2134 | G7: 0.2074
A8: Cost of Revenue | B8: 7315 | C8: 7454 | D8: 7605 | E8: 7554 | F8: 8970 | G8: 7376
A9: Gross Profit | B9: 1587 | C9: 1614 | D9: 1939 | E9: 1960 | F9: 2580 | G9: 2143
A10: Selling, General & Admin | B10: 912.8 | C10: 923 | D10: 935 | E10: 892 | F10: 858 | G10: 788
A11: Research & Development | B11: 283.9 | C11: 284 | D11: 278 | E11: 275 | F11: 270 | G11: 243
A12: Other Operating Expenses | B12: 3.8 | C12: 3 | D12: 51 | E12: 67 | F12: 33 | G12: 21
A13: Operating Expenses | B13: 1201 | C13: 1210 | D13: 1264 | E13: 1234 | F13: 1161 | G13: 1052
A14: Operating Income | B14: 386.3 | C14: 404 | D14: 675 | E14: 726 | F14: 1419 | G14: 1091
A15: Interest Expense | B15: -84.3 | C15: -76 | D15: -30 | E15: -25 | F15: -44 | G15: -49
A16: Earnings From Equity Investments | B16: -1.2 | C16: -1 | D16: -6 | E16: -9 | F16: -6 | G16: -1
A17: Currency Exchange Gain (Loss) | B17: -32.2 | C17: -36 | D17: -28 | E17: -27 | F17: -27 | G17: -3
A18: Other Non Operating Income (Expenses) | B18: 0.2 | C18: - | D18: - | E18: - | F18: - | G18: -
A19: EBT Excluding Unusual Items | B19: 268.8 | C19: 291 | D19: 611 | E19: 665 | F19: 1342 | G19: 1038
A20: Merger & Restructuring Charges | B20: -79.2 | C20: -103 | D20: -44 | E20: -52 | F20: -51 | G20: -37
A21: Impairment of Goodwill | B21: - | C21: - | D21: - | E21: - | F21: - | G21: -41
A22: Gain (Loss) on Sale of Assets | B22: -19.8 | C22: -18 | D22: -30 | E22: 11 | F22: -24 | G22: 934
A23: Asset Writedown | B23: - | C23: - | D23: -11 | E23: -28 | F23: -33 | G23: -191
A24: Legal Settlements | B24: -17.5 | C24: -8 | D24: -19 | E24: 6 | F24: -14 | G24: -27
A25: Pretax Income | B25: 152.3 | C25: 162 | D25: 507 | E25: 602 | F25: 1220 | G25: 1676
A26: Income Tax Expense | B26: 90.3 | C26: 100 | D26: 150 | E26: 177 | F26: 254 | G26: 369
A27: Earnings From Continuing Operations | B27: 62 | C27: 62 | D27: 357 | E27: 425 | F27: 966 | G27: 1307
A28: Minority Interest in Earnings | B28: -2.5 | C28: 1 | D28: -3 | E28: -7 | F28: -1 | G28: 2
A29: Net Income | B29: 59.5 | C29: 63 | D29: 354 | E29: 418 | F29: 965 | G29: 1309
A30: Preferred Dividends & Other Adjustments | B30: 41 | C30: 24 | D30: 16 | E30: 16 | F30: 16 | G30: 16
A31: Net Income to Common | B31: 18.5 | C31: 39 | D31: 338 | E31: 402 | F31: 949 | G31: 1293
A32: Net Income Growth | B32: -0.9009 | C32: -0.8846 | D32: -0.1592 | E32: -0.5764 | F32: -0.2661 | G32: 3.2533
A33: Shares Outstanding (Basic) | B33: 76 | C33: 76 | D33: 75 | E33: 75 | F33: 74 | G33: 75
A34: Shares Outstanding (Diluted) | B34: 76 | C34: 76 | D34: 75 | E34: 75 | F34: 74 | G34: 76
A35: Shares Change | B35: -0.0218 | C35: 0.0101 | D35: 0.0021 | E35: 0.0084 | F35: -0.019 | G35: -0.011
... A38: EPS Growth | B38: -0.9008 | C38: -0.8864 | D38: -0.1623 | E38: -0.5796 | F38: -0.2518 | G38: 3.303
A40: Balance Sheet
A41: Assets
A42: Fiscal Year | B42: TTM | C42: FY 2025 | D42: FY 2024 | E42: FY 2023 | F42: FY 2022 | G42: FY 2021
A43: Period Ending | B43: Jun 30, 2026 | C43: Dec 31, 2025 | D43: Dec 31, 2024 | E43: Dec 31, 2023 | F43: Dec 31, 2022 | G43: Dec 31, 2021
A44: Cash & Equivalents | B44: 1467 | C44: 2188 | D44: 2013 | E44: 2045 | F44: 1592 | G44: 2285
...

Sheet Solvay SA
A1: Solvay SA (EBR:SOLB)
A2: Income Statement
A3: Fiscal Year | B3: TTM | C3: FY 2025 | D3: FY 2024 | E3: FY 2023 | F3: FY 2022 | G3: FY 2021
A4: Period Ending | B4: Jun 30, 2026 | C4: Dec 31, 2025 | D4: Dec 31, 2024 | E4: Dec 31, 2023 | F4: Dec 31, 2022 | G4: Dec 31, 2021
A5: Operating Revenue | B5: 3929 | C5: 4123 | D5: 4540 | E5: 4880 | F5: 5539 | G5: 10105
A6: Other Revenue | B6: 645 | C6: 623 | D6: 590 | E6: 1145 | F6: 2440 | G6: 1329
A7: Revenue | B7: 4574 | C7: 4746 | D7: 5130 | E7: 6025 | F7: 7979 | G7: 11434
A8: Revenue Growth | B8: -0.0767 | C8: -0.0749 | D8: -0.1485 | E8: -0.2449 | F8: -0.3022 | G8: 0.1771
A9: Cost of Revenue | B9: 3596 | C9: 3743 | D9: 3984 | E9: 4642 | F9: 6554 | G9: 8508
A10: Gross Profit | B10: 978 | C10: 1003 | D10: 1146 | E10: 1383 | F10: 1425 | G10: 2926
A11: Selling, General & Admin | B11: 542 | C11: 509 | D11: 419 | E11: 526 | F11: 565 | G11: 1233
A12: Research & Development | B12: 26 | C12: 23 | D12: 34 | E12: 47 | F12: 46 | G12: 325
A13: Other Operating Expenses | B13: 45 | C13: 36 | D13: 97 | E13: -10 | F13: -310 | G13: 157
A14: Operating Expenses | B14: 613 | C14: 568 | D14: 550 | E14: 563 | F14: 301 | G14: 1715
A15: Operating Income | B15: 365 | C15: 435 | D15: 596 | E15: 820 | F15: 1124 | G15: 1211
A16: Interest Expense | B16: -98 | C16: -99 | D16: -108 | E16: -65 | F16: -43 | G16: -99
... A18: Earnings From Equity Investments | B18: 37 | C18: 39 | D18: 38 | E18: 53 | F18: 153 | G18: 158
A19: Currency Exchange Gain (Loss) | B19: -2 | C19: -2 | D19: -3 | E19: 3 | F19: 24 | G19: -
A20: Other Non Operating Income (Expenses) | B20: -6 | C20: -2 | D20: 2 | E20: -74 | F20: 23 | G20: -5
A21: EBT Excluding Unusual Items | B21: 305 | C21: 382 | D21: 543 | E21: 773 | F21: 1297 | G21: 1274
A22: Merger & Restructuring Charges | B22: -90 | C22: -77 | D22: -89 | E22: -455 | F22: -96 | G22: -228
A23: Impairment of Goodwill | B23: -29 | C23: -29 | D23: - | E23: -38 | F23: - | G23: -
A24: Gain (Loss) on Sale of Investments | B24: 1 | C24: -1 | D24: -22 | E24: 4 | F24: - | G24: 9
A25: Gain (Loss) on Sale of Assets | B25: 5 | C25: 16 | D25: 6 | E25: 3 | F25: 3 | G25: 12
A26: Asset Writedown | B26: -50 | C26: -58 | D26: -45 | E26: -57 | F26: 37 | G26: -
A27: Legal Settlements | B27: -5 | C27: 2 | D27: -1 | E27: -12 | F27: - | G27: 61
A28: Other Unusual Items | B28: -19 | C28: -78 | D28: -72 | E28: -38 | F28: -110 | G28: -34
A29: Pretax Income | B29: 118 | C29: 157 | D29: 320 | E29: 180 | F29: 1131 | G29: 1094
A30: Income Tax Expense | B30: 109 | C30: 120 | D30: 87 | E30: 208 | F30: 228 | G30: 110
A31: Earnings From Continuing Operations | B31: 9 | C31: 37 | D31: 233 | E31: -28 | F31: 903 | G31: 984
A32: Earnings From Discontinued Operations | B32: - | C32: - | D32: - | E32: 2130 | F32: 1016 | G32: 5
A33: Net Income to Company | B33: 9 | C33: 37 | D33: 233 | E33: 2102 | F33: 1919 | G33: 989
A34: Minority Interest in Earnings | B34: -5 | C34: -7 | D34: -10 | E34: -9 | F34: -14 | G34: -41
A35: Net Income | B35: 4 | C35: 30 | D35: 223 | E35: 2093 | F35: 1905 | G35: 948
A36: Net Income to Common | B36: 4 | C36: 30 | D36: 223 | E36: 2093 | F36: 1905 | G36: 948
A37: Net Income Growth | B37: -0.9712 | C37: -0.8655 | D37: -0.8934 | E37: 0.0987 | F37: 1.0095 | G37: -
A38: Shares Outstanding (Basic) | B38: 105 | C38: 104 | D38: 105 | E38: 104 | F38: 104 | G38: 104
A39: Shares Outstanding (Diluted) | B39: 105 | C39: 105 | D39: 106 | E39: 104 | F39: 104 | G39: 104
A40: Shares Change | B40: -0.0016 | C40: -0.0053 | D40: 0.0182 | E40: 0.0002 | F40: 0.0034 | G40: 0.0063
A41: EPS (Basic) | B41: 0.04 | C41: 0.29 | D41: 2.12 | E41: 20.09 | F41: 18.36 | G41: 9.16
...

Sheet Comparable & M&A
A1: BASF SE — Comparable Company & M&A Analysis
A2: Model basis: FY2025 reported data for BASF/Covestro; peer inputs retained from the original project; M&A assumptions retained unless explicitly audited.
A3: Comparable Company Analysis
A4: Company | B4: Revenue (€m) | C4: EBITDA (€m) | D4: Enterprise Value (€m) | E4: Market Cap (€m) | F4: Net Debt (€m) | G4: EV/EBITDA
A5: BASF | B5: 59657 | C5: 5618 | D5: =E5+F5 -> 57982.775 | E5: 39653.775 | F5: 18329 | G5: =D5/C5 -> 10.320893
A6: Covestro | B6: 12942 | C6: 740 | D6: =E6+F6 -> 14250.267 | E6: 12454.267 | F6: 1796 | G6: =D6/C6 -> 19.257118
A7: Evonik | B7: 14069 | C7: 1899 | D7: =E7+F7 -> 8569 | E7: 6058 | F7: 2511 | G7: =D7/C7 -> 4.5123749
A8: Arkema | B8: 9068 | C8: 1242 | D8: =E8+F8 -> 6030.834 | E8: 4018.834 | F8: 2012 | G8: =D8/C8 -> 4.855744
A9: Solvay | B9: 4746 | C9: 747 | D9: =E9+F9 -> 4130.6035 | E9: 2875.6035 | F9: 1255 | G9: =D9/C9 -> 5.5295896
A10: Median | G10: =MEDIAN(G5:G9) -> 5.5295896
A12: M&A Purchase Price — BASF Target / Covestro Acquirer
A13: BASF SE — Comparable Company & M&A Analysis
A14: BASF Share Price (€) | B14: 44.43 | C14: Covestro | D14: Evonik | E14: Arkema | F14: Solvay
A15: Acquisition Premium | B15: 0.2 | C15: 12942 | D15: 14069 | E15: 9068 | F15: 4746
A16: Offer Price (€) | B16: 53.316 | C16: 619 | D16: 1899 | E16: 1242 | F16: 747
A17: Diluted Shares (m) | B17: 894.057 | C17: 14273.267 | D17: 8569 | E17: 6030.834 | F17: 4130.6035
A18: Equity Purchase Price (€m) | B18: =B16*B17 -> 47667.543 | C18: 12454.267 | D18: 6058 | E18: 4018.834 | F18: 2875.6035
A19: Existing Debt / Refinancing (€m) | B19: 23209 | C19: 1819 | D19: 2511 | E19: 2012 | F19: 1255
A20: Transaction Fees (€m) | B20: =B18*1% -> 476.67543 | C20: 1.1028641 | D20: 0.60906959 | E20: 0.66506771 | F20: 0.87033364
A21: Total Uses (€m) | B21: =B18+B19+B20 -> 71353.218 | C21: 23.05859 | D21: 4.5123749 | E21: 4.855744 | F21: 5.5295896
A23: M&A Premium Sensitivity
A24: Metric | B24: 10% | C24: 15% | D24: 20% | E24: 25% | F24: 30% | G24: Formula / assumption
A25: Acquisition Premium | B25: 0.1 | C25: 0.15 | D25: 0.2 | E25: 0.25 | F25: 0.3 | G25: Input
A26: Offer Price per Share (€) | B26: =$B$15*(1+B25) -> 0.22 | C26: =$B$15*(1+C25) -> 0.23 | D26: =$B$15*(1+D25) -> 0.24 | E26: =$B$15*(1+E25) -> 0.25 | F26: =$B$15*(1+F25) -> 0.26 | G26: BASF €44.43 × (1 + premium)
A27: Equity Purchase Price (€m) | B27: =B26*894.057 -> 196.69254 | C27: =C26*894.057 -> 205.63311 | D27: =D26*894.057 -> 214.57368 | E27: =E26*894.057 -> 223.51425 | F27: =F26*894.057 -> 232.45482 | G27: Offer price × 894.057m
A28: Refinancing / Existing Debt (€m) | B28: 23209 | C28: 23209 | D28: 23209 | E28: 23209 | F28: 23209 | G28: Fixed BASF existing debt
A29: Transaction Fees (€m) | B29: =B27*1% -> 1.9669254 | C29: =C27*1% -> 2.0563311 | D29: =D27*1% -> 2.1457368 | E29: =E27*1% -> 2.2351425 | F29: =F27*1% -> 2.3245482 | G29: 1% × equity purchase price
A30: Total Uses (€m) | B30: =B27+B28+B29 -> 23407.659 | C30: =C27+C28+C29 -> 23416.689 | D30: =D27+D28+D29 -> 23425.719 | E30: =E27+E28+E29 -> 23434.749 | F30: =F27+F28+F29 -> 23443.779 | G30: Purchase price + debt + fees
A31: Cash on Balance Sheet (€m) | B31: 648 | C31: 648 | D31: 648 | E31: 648 | F31: 648 | G31: Covestro cash
A32: New Debt (€m) | B32: =B30*50% -> 11703.83 | C32: =C30*50% -> 11708.345 | D32: =D30*50% -> 11712.86 | E32: =E30*50% -> 11717.375 | F32: =F30*50% -> 11721.89 | G32: 50% × total uses
A33: Equity Issuance (€m) | B33: =B30-B31-B32 -> 11055.83 | C33: =C30-C31-C32 -> 11060.345 | D33: =D30-D31-D32 -> 11064.86 | E33: =E30-E31-E32 -> 11069.375 | F33: =F30-F31-F32 -> 11073.89 | G33: Total uses − cash − new debt
A34: New Interest Expense (€m) | B34: =-B32*5% -> -585.19149 | C34: =-C32*5% -> -585.41724 | D34: =-D32*5% -> -585.64299 | E34: =-E32*5% -> -585.86873 | F34: =-F32*5% -> -586.09448 | G34: 5% × new debt
A35: Pro Forma Net Income (€m) | B35: =-644+1619+((1234.28+B34)-(1234.28+B34)*30%) -> 1429.362 | C35: =-644+1619+((1234.28+C34)-(1234.28+C34)*30%) -> 1429.2039 | D35: =-644+1619+((1234.28+D34)-(1234.28+D34)*30%) -> 1429.0459 | E35: =-644+1619+((1234.28+E34)-(1234.28+E34)*30%) -> 1428.8879 | F35: =-644+1619+((1234.28+F34)-(1234.28+F34)*30%) -> 1428.7299 | G35: Standalone NI + synergy/tax/interest adjustment
A36: New Shares Issued (m) | B36: =B33/59.98 -> 184.32527 | C36: =C33/59.98 -> 184.40055 | D36: =D33/59.98 -> 184.47582 | E36: =E33/59.98 -> 184.5511 | F36: =F33/59.98 -> 184.62637 | G36: Equity issuance ÷ Covestro share price €59.98
A37: Pro Forma Diluted Shares (m) | B37: =189.879508+B36 -> 374.20478 | C37: =189.879508+C36 -> 374.28005 | D37: =189.879508+D36 -> 374.35533 | E37: =189.879508+E36 -> 374.4306 | F37: =189.879508+F36 -> 374.50588 | G37: 189.879508m + new shares
A38: Pro Forma EPS (€) | B38: =B35/B37 -> 3.819732 | C38: =C35/C37 -> 3.8185415 | D38: =D35/D37 -> 3.8173516 | E38: =E35/E37 -> 3.8161621 | F38: =F35/F37 -> 3.8149731 | G38: Pro forma NI ÷ pro forma shares
A39: EPS Improvement (€) | B39: =B38-(-644/189.879508) -> 7.2113565 | C39: =C38-(-644/189.879508) -> 7.2101661 | D39: =D38-(-644/189.879508) -> 7.2089761 | E39: =E38-(-644/189.879508) -> 7.2077867 | F39: =F38-(-644/189.879508) -> 7.2065977 | G39: Pro forma EPS − standalone EPS
A40: EPS Accretion / (Dilution) (%) | B40: N/M | C40: N/M | D40: N/M | E40: N/M | F40: N/M | G40: N/M because standalone EPS is negative
A41: Implied EV — EV/Revenue | B41: 51921.494
A42: Implied EV — EV/EBITDA | B42: 33470.606
...

Sheet CCA & M&A Audit
A1: Project 4 — CCA & M&A Audit
A3: Company | B3: Revenue (€m) | C3: EBITDA (€m) | D3: EV (€m) | E3: Market Cap (€m) | F3: Net Debt (€m) | G3: EV/EBITDA
A4: BASF | B4: 59657 | C4: 5618 | D4: =E4+F4 -> 57982.775 | E4: 39653.775 | F4: 18329 | G4: =D4/C4 -> 10.320893
A5: Covestro | B5: 12942 | C5: 740 | D5: =E5+F5 -> 14250.267 | E5: 12454.267 | F5: 1796 | G5: =D5/C5 -> 19.257118
A6: Evonik | B6: 14069 | C6: 1899 | D6: =E6+F6 -> 8569 | E6: 6058 | F6: 2511 | G6: =D6/C6 -> 4.5123749
A7: Arkema | B7: 9068 | C7: 1242 | D7: =E7+F7 -> 6030.834 | E7: 4018.834 | F7: 2012 | G7: =D7/C7 -> 4.855744
A8: Solvay | B8: 4746 | C8: 747 | D8: =E8+F8 -> 4130.6035 | E8: 2875.6035 | F8: 1255 | G8: =D8/C8 -> 5.5295896
A9: Median | G9: =MEDIAN(G4:G8) -> 5.5295896
A11: Data note: BASF/Covestro FY2025 figures are aligned to official annual reports; other peer inputs are retained from the original project.
A12: BASF: Revenue €59,657m, EBITDA €5,618m, Net Debt €18,329m. Covestro: Revenue €12,942m, EBITDA €740m, Net Financial Debt €1,796m. | B12: BASF | C12: Covestro | D12: Evonik | E12: Arkema | F12: Solvay | G12: Median
A13: EV / Revenue | B13: =D4/B4 -> 0.97193582 | C13: =D5/B5 -> 1.1010869 | D13: =D6/B6 -> 0.60906959 | E13: =D7/B7 -> 0.66506771 | F13: =D8/B8 -> 0.87033364 | G13: =MEDIAN(B13:F13) -> 0.87033364
A14: Median EV/Revenue | G14: =G13 -> 0.87033364
A17: M&A — Covestro Acquirer / BASF Target
A18: BASF Share Price (€) | B18: 44.43
A19: Acquisition Premium | B19: 0.2
A20: Offer Price per Share (€) | B20: =B18*(1+B19) -> 53.316
A21: BASF Diluted Shares (m) | B21: 894.057
A22: Equity Purchase Price (€m) | B22: =B20*B21 -> 47667.543
A23: Refinancing / Existing Debt (€m) | B23: 23209
A24: Transaction Fees (€m) | B24: =B22*1% -> 476.67543
A25: Total Uses (€m) | B25: =B22+B23+B24 -> 71353.218
A26: Cash on Balance Sheet (€m) | B26: 648
A27: New Debt (€m) | B27: =B25*50% -> 35676.609
A28: Equity Issuance (€m) | B28: =B25-B26-B27 -> 35028.609
A29: New Interest Expense (€m) | B29: =-B27*5% -> -1783.8305
A30: Realized Synergies (€m) | B30: 1234.28
A31: Pro Forma Net Income (€m) | B31: =-644+1619+((B30+B29)-(B30+B29)*30%) -> 590.31468
A32: Covestro Diluted Shares (m) | B32: 189.87951
A33: New Shares Issued (m) | B33: =B28/59.98 -> 584.00482
A34: Pro Forma Diluted Shares (m) | B34: =B32+B33 -> 773.88433
A35: Standalone Covestro EPS (€) | B35: =-644/B32 -> -3.3916245
A36: Pro Forma EPS (€) | B36: =B31/B34 -> 0.76279446
A37: EPS Improvement (€) | B37: =B36-B35 -> 4.154419
A38: EPS Accretion / (Dilution) (%) | B38: =IF(B35<=0,"N/M",B36/B35-1) -> N/M
A39: M&A Premium Sensitivity
A40: Metric | B40: 10% | C40: 15% | D40: 20% | E40: 25% | F40: 30% | G40: Formula
A41: Acquisition Premium | B41: 0.1 | C41: 0.15 | D41: 0.2 | E41: 0.25 | F41: 0.3 | G41: Input
A42: Offer Price per Share (€) | B42: =$B$18*(1+B41) -> 48.873 | C42: =$B$18*(1+C41) -> 51.0945 | D42: =$B$18*(1+D41) -> 53.316 | E42: =$B$18*(1+E41) -> 55.5375 | F42: =$B$18*(1+F41) -> 57.759 | G42: BASF €44.43 × (1 + premium)
A43: Equity Purchase Price (€m) | B43: =B42*$B$21 -> 43695.248 | C43: =C42*$B$21 -> 45681.395 | D43: =D42*$B$21 -> 47667.543 | E43: =E42*$B$21 -> 49653.691 | F43: =F42*$B$21 -> 51639.838 | G43: Offer price × 894.057m diluted shares
A44: Refinancing / Existing Debt (€m) | B44: =$B$23 -> 23209 | C44: =$B$23 -> 23209 | D44: =$B$23 -> 23209 | E44: =$B$23 -> 23209 | F44: =$B$23 -> 23209 | G44: Fixed BASF existing debt
...

Sheet Model Checks
A1: Project 4 — Model Checks
A2: Check | B2: Result | C2: Status
A3: Check | B3: Result | C3: Status
A4: DCF EV reconciliation | B4: =ABS('DCF Valuation'!B40-('DCF Valuation'!B36+'DCF Valuation'!B39))<0.01 -> TRUE | C4: =IF(B4,"PASS","FAIL") -> PASS
A5: DCF equity value reconciliation | B5: =ABS('DCF Valuation'!B42-('DCF Valuation'!B40-'DCF Valuation'!B41))<0.01 -> TRUE | C5: =IF(B5,"PASS","FAIL") -> PASS
A6: CCA five companies | B6: =COUNTA('CCA & M&A Audit'!A4:A8)=5 -> TRUE | C6: =IF(B6,"PASS","FAIL") -> PASS
A7: CCA median EV/EBITDA | B7: =ABS('CCA & M&A Audit'!G9-MEDIAN('CCA & M&A Audit'!G4:G8))<0.0001 -> TRUE | C7: =IF(B7,"PASS","FAIL") -> PASS
A8: CCA median EV/Revenue | B8: =ABS('CCA & M&A Audit'!G13-MEDIAN('CCA & M&A Audit'!B13:F13))<0.0001 -> TRUE | C8: =IF(B8,"PASS","FAIL") -> PASS
A9: M&A 20% equity purchase price | B9: =ABS('CCA & M&A Audit'!D43-47667.543012)<0.01 -> TRUE | C9: =IF(B9,"PASS","FAIL") -> PASS
A10: M&A 20% total uses | B10: =ABS('CCA & M&A Audit'!D46-71353.21844212)<0.01 -> TRUE | C10: =IF(B10,"PASS","FAIL") -> PASS
A11: M&A 20% pro forma EPS | B11: =ABS('CCA & M&A Audit'!D54-0.762794457)<0.001 -> TRUE | C11: =IF(B11,"PASS","FAIL") -> PASS
A12: CCA EV/Revenue median | B12: =ABS('CCA & M&A Audit'!G13-MEDIAN('CCA & M&A Audit'!B13:F13))<0.0001 -> TRUE | C12: =IF(B12,"PASS","FAIL") -> PASS
A13: LBO entry capital | B13: ='LBO Analysis'!B72 -> TRUE | C13: =IF(B13,"PASS","FAIL") -> PASS
A14: LBO debt non-negative | B14: ='LBO Analysis'!B73 -> TRUE | C14: =IF(B14,"PASS","FAIL") -> PASS
A15: LBO exit equity | B15: ='LBO Analysis'!B74 -> TRUE | C15: =IF(B15,"PASS","FAIL") -> PASS
A16: LBO MOIC | B16: ='LBO Analysis'!B75 -> TRUE | C16: =IF(B16,"PASS","FAIL") -> PASS

Sheet LBO Analysis
A1: BASF SE — Illustrative LBO Analysis
A2: Purpose | B2: Illustrative sponsor LBO using BASF FY2025 reported results and the existing M&A offer framework.
A3: Currency | B3: € million, except per-share data and multiples
A5: 1. Entry Assumptions
A6: Assumption | B6: Value | C6: Formula / Note
A7: Target Share Price (€) | B7: 44.43 | C7: Existing project transaction assumption
A8: Acquisition Premium | B8: 0.2 | C8: Existing project assumption
A9: Offer Price / Share (€) | B9: =B7*(1+B8) -> 53.316 | C9: Share price × (1 + premium)
A10: Diluted Shares (m) | B10: 894.057 | C10: Existing project assumption
A11: Equity Purchase Price (€m) | B11: =B9*B10 -> 47667.543 | C11: Offer price × diluted shares
A12: BASF Net Debt (€m) | B12: 18329 | C12: FY2025 reported net debt
A13: Entry Enterprise Value (€m) | B13: =B11+B12 -> 65996.543 | C13: Equity purchase price + net debt
A14: Entry EBITDA (€m) | B14: 5618 | C14: FY2025 reported EBITDA
A15: Entry EV / EBITDA | B15: =B13/B14 -> 11.747338 | C15: Entry EV ÷ EBITDA
A16: Entry Debt / EBITDA | B16: =B19/B14 -> 5.8736688 | C16: Entry debt ÷ EBITDA
A17: Debt Financing % | B17: 0.5 | C17: Illustrative assumption
A18: Sponsor Equity Financing % | B18: 0.5 | C18: Illustrative assumption
A19: Entry Debt (€m) | B19: =B13*B17 -> 32998.272 | C19: Debt financing % × entry EV
A20: Sponsor Equity (€m) | B20: =B13-B19 -> 32998.272 | C20: Entry EV less entry debt
A21: Interest Rate | B21: 0.06 | C21: Illustrative acquisition debt rate
A22: Tax Rate | B22: 0.3 | C22: Illustrative tax rate
A23: Revenue Growth | B23: 0.03 | C23: Illustrative annual growth
A24: EBITDA Margin | B24: =B14/59657 -> 0.094171681 | C24: FY2025 EBITDA / revenue
A25: Capex % Revenue | B25: 0.03 | C25: Illustrative assumption
A26: Change in NWC % of Revenue Growth | B26: 0.005 | C26: Illustrative assumption
A27: Exit EV / EBITDA | B27: 9 | C27: Illustrative exit multiple
A28: Holding Period (Years) | B28: 5 | C28: Five-year LBO case
A31: 2. Operating & Debt Paydown Forecast
A32: Metric | B32: FY2026F | C32: FY2027F | D32: FY2028F | E32: FY2029F | F32: FY2030F | G32: Formula / Note
A33: Revenue (€m) | B33: =59657*(1+$B$23) -> 61446.71 | C33: =B33*(1+$B$23) -> 63290.111 | D33: =C33*(1+$B$23) -> 65188.815 | E33: =D33*(1+$B$23) -> 67144.479 | F33: =E33*(1+$B$23) -> 69158.813 | G33: Revenue grows at 3.0% annually
A34: EBITDA (€m) | B34: =B33*$B$24 -> 5786.54 | C34: =C33*$B$24 -> 5960.1362 | D34: =D33*$B$24 -> 6138.9403 | E34: =E33*$B$24 -> 6323.1085 | F34: =F33*$B$24 -> 6512.8017 | G34: Revenue × FY2025 EBITDA margin
A35: D&A (€m) | B35: =B33*4% -> 2457.8684 | C35: =C33*4% -> 2531.6045 | D35: =D33*4% -> 2607.5526 | E35: =E33*4% -> 2685.7792 | F35: =F33*4% -> 2766.3525 | G35: Illustrative D&A = 4% of revenue
A36: EBIT (€m) | B36: =B34-B35 -> 3328.6716 | C36: =C34-C35 -> 3428.5317 | D36: =D34-D35 -> 3531.3877 | E36: =E34-E35 -> 3637.3293 | F36: =F34-F35 -> 3746.4492 | G36: EBIT = EBITDA − D&A
A37: Cash Interest (€m) | B37: =-B43*$B$21 -> -1979.8963 | C37: =-C43*$B$21 -> -1886.9166 | D37: =-D43*$B$21 -> -1784.7477 | E37: =-E43*$B$21 -> -1672.8452 | F37: =-F43*$B$21 -> -1550.6369 | G37: Interest on beginning debt
A38: EBT (€m) | B38: =B36+B37 -> 1348.7753 | C38: =C36+C37 -> 1541.6151 | D38: =D36+D37 -> 1746.64 | E38: =E36+E37 -> 1964.4842 | F38: =F36+F37 -> 2195.8124 | G38: EBIT − cash interest
A39: Cash Taxes (€m) | B39: =MAX(0,B38*$B$22) -> 404.63259 | C39: =MAX(0,C38*$B$22) -> 462.48454 | D39: =MAX(0,D38*$B$22) -> 523.99199 | E39: =MAX(0,E38*$B$22) -> 589.34525 | F39: =MAX(0,F38*$B$22) -> 658.74371 | G39: 30% tax on positive EBT
A40: Capex (€m) | B40: =-B33*$B$25 -> -1843.4013 | C40: =-C33*$B$25 -> -1898.7033 | D40: =-D33*$B$25 -> -1955.6644 | E40: =-E33*$B$25 -> -2014.3344 | F40: =-F33*$B$25 -> -2074.7644 | G40: Capex = 3% of revenue
A41: Change in NWC (€m) | B41: =-(B33-59657)*$B$26 -> -8.94855 | C41: =-(C33-B33)*$B$26 -> -9.2170065 | D41: =-(D33-C33)*$B$26 -> -9.4935167 | E41: =-(E33-D33)*$B$26 -> -9.7783222 | F41: =-(F33-E33)*$B$26 -> -10.071672 | G41: NWC investment = 0.5% of revenue growth
A42: Cash Flow Available for Debt Paydown (€m) | B42: =B34+B37-B39+B40+B41 -> 1549.6613 | C42: =C34+C37-C39+C40+C41 -> 1702.8147 | D42: =D34+D37-D39+D40+D41 -> 1865.0426 | E42: =E34+E37-E39+E40+E41 -> 2036.8054 | F42: =F34+F37-F39+F40+F41 -> 2218.5851 | G42: Cash after interest, tax, capex and NWC
A43: Beginning Debt (€m) | B43: =$B$19 -> 32998.272 | C43: =B45 -> 31448.61 | D43: =C45 -> 29745.796 | E43: =D45 -> 27880.753 | F43: =E45 -> 25843.948
...
